<sdf version='1.9'>
  <world name='empty'>
    <physics name='1ms' type='ignored'>
      <max_step_size>0.001</max_step_size>
      <real_time_factor>1</real_time_factor>
      <real_time_update_rate>1000</real_time_update_rate>
    </physics>
    <plugin name='gz::sim::systems::Physics' filename='gz-sim-physics-system'/>
    <plugin name='gz::sim::systems::UserCommands' filename='gz-sim-user-commands-system'/>
    <plugin name='gz::sim::systems::SceneBroadcaster' filename='gz-sim-scene-broadcaster-system'/>
    <plugin name='gz::sim::systems::Sensors' filename='gz-sim-sensors-system'>
      <render_engine>ogre2</render_engine>
    </plugin>
    <plugin name='gz::sim::systems::Contact' filename='gz-sim-contact-system'/>
    <gravity>0 0 -9.8</gravity>
    <magnetic_field>6e-06 2.3e-05 -4.2e-05</magnetic_field>
    <atmosphere type='adiabatic'/>
    <scene>
      <ambient>0.4 0.4 0.4 1</ambient>
      <background>0.7 0.7 0.7 1</background>
      <shadows>true</shadows>
    </scene>
    <model name='ground_plane'>
      <static>true</static>
      <link name='link'>
        <collision name='collision'>
          <geometry>
            <plane>
              <normal>0 0 1</normal>
              <size>100 100</size>
            </plane>
          </geometry>
          <surface>
            <friction>
              <ode/>
            </friction>
            <bounce/>
            <contact/>
          </surface>
        </collision>
        <visual name='visual'>
          <geometry>
            <plane>
              <normal>0 0 1</normal>
              <size>100 100</size>
            </plane>
          </geometry>
          <material>
            <ambient>0.8 0.8 0.8 1</ambient>
            <diffuse>0.8 0.8 0.8 1</diffuse>
            <specular>0.8 0.8 0.8 1</specular>
          </material>
        </visual>
        <pose>0 0 0 0 -0 0</pose>
        <inertial>
          <pose>0 0 0 0 -0 0</pose>
          <mass>1</mass>
          <inertia>
            <ixx>1</ixx>
            <ixy>0</ixy>
            <ixz>0</ixz>
            <iyy>1</iyy>
            <iyz>0</iyz>
            <izz>1</izz>
          </inertia>
        </inertial>
        <enable_wind>false</enable_wind>
      </link>
      <pose>0 0 0 0 -0 0</pose>
      <self_collide>false</self_collide>
    </model>
    <model name='agv'>
      <link name='base_link'>
        <inertial>
          <pose>0.492975 0 -0.00062 0 -0 0</pose>
          <mass>12.1</mass>
          <inertia>
            <ixx>0.43507899999999999</ixx>
            <ixy>0</ixy>
            <ixz>0.113678</ixz>
            <iyy>1.5306500000000001</iyy>
            <iyz>3.4694499999999997e-18</iyz>
            <izz>1.8595999999999999</izz>
          </inertia>
        </inertial>
        <collision name='base_link_collision'>
          <pose>0.1 0 0.1 0 0 0</pose>
          <geometry>
            <box>
              <size>0.2 0.5 0.2</size>
            </box>
          </geometry>
          <surface>
            <friction>
              <ode/>
            </friction>
            <bounce/>
            <contact/>
          </surface>
        </collision>
        <collision name='base_link_fixed_joint_lump__laser_collision_1'>
          <pose>0.075 0 0.2125 0 0 0</pose>
          <geometry>
            <cylinder>
              <length>0.025000000000000001</length>
              <radius>0.025000000000000001</radius>
            </cylinder>
          </geometry>
          <surface>
            <contact>
              <ode/>
            </contact>
            <friction>
              <ode/>
            </friction>
            <bounce/>
          </surface>
        </collision>
        <collision name='base_link_fixed_joint_lump__left_fork_collision_2'>
          <pose>0.575 0.18 -0.025 0 0 0</pose>
          <geometry>
            <box>
              <size>1.15 0.14 0.05</size>
            </box>
          </geometry>
          <surface>
            <friction>
              <ode/>
            </friction>
            <bounce/>
            <contact/>
          </surface>
        </collision>
        <collision name='base_link_fixed_joint_lump__right_fork_collision_3'>
          <pose>0.575 -0.18 -0.025 0 0 0</pose>
          <geometry>
            <box>
              <size>1.15 0.14 0.05</size>
            </box>
          </geometry>
          <surface>
            <friction>
              <ode/>
            </friction>
            <bounce/>
            <contact/>
          </surface>
        </collision>
        <visual name='base_link_visual'>
          <pose>0.1 0 0.1 0 0 0</pose>
          <geometry>
            <box>
              <size>0.2 0.5 0.2</size>
            </box>
          </geometry>
          <material>
            <diffuse>0 0 0 1</diffuse>
            <ambient>0 0 0 1</ambient>
          </material>
        </visual>
        <visual name='base_link_fixed_joint_lump__laser_visual_1'>
          <pose>0.075 0 0.2125 0 0 0</pose>
          <geometry>
            <cylinder>
              <length>0.025000000000000001</length>
              <radius>0.025000000000000001</radius>
            </cylinder>
          </geometry>
          <material>
            <script>
              <name>Gazebo/Orange</name>
              <uri>file://media/materials/scripts/gazebo.material</uri>
            </script>
            <diffuse>1 0.375 0.125 1</diffuse>
            <ambient>1 0.375 0.125 1</ambient>
          </material>
        </visual>
        <visual name='base_link_fixed_joint_lump__left_fork_visual_2'>
          <pose>0.575 0.18 -0.025 0 0 0</pose>
          <geometry>
            <box>
              <size>1.15 0.14 0.05</size>
            </box>
          </geometry>
          <material>
            <diffuse>1 1 1 1</diffuse>
            <ambient>1 1 1 1</ambient>
          </material>
        </visual>
        <visual name='base_link_fixed_joint_lump__right_fork_visual_3'>
          <pose>0.575 -0.18 -0.025 0 0 0</pose>
          <geometry>
            <box>
              <size>1.15 0.14 0.05</size>
            </box>
          </geometry>
          <material>
            <diffuse>1 1 1 1</diffuse>
            <ambient>1 1 1 1</ambient>
          </material>
        </visual>
        <sensor name='head_hokuyo_sensor' type='gpu_lidar'>
          <pose>0.15 0 0.425 0 -0 0</pose>
          <topic>scan</topic>
          <update_rate>10</update_rate>
          <enable_metrics>false</enable_metrics>
          <lidar>
            <scan>
              <horizontal>
                <samples>270</samples>
                <resolution>1</resolution>
                <min_angle>-2.0943000000000001</min_angle>
                <max_angle>2.0943000000000001</max_angle>
              </horizontal>
              <vertical>
                <samples>1</samples>
                <min_angle>0</min_angle>
                <max_angle>0</max_angle>
                <resolution>1</resolution>
              </vertical>
            </scan>
            <range>
              <min>0.10000000000000001</min>
              <max>20</max>
              <resolution>0</resolution>
            </range>
            <noise>
              <type>none</type>
              <mean>0</mean>
              <stddev>0</stddev>
            </noise>
            <visibility_mask>4294967295</visibility_mask>
          </lidar>
        </sensor>
        <pose>0 0 0 0 -0 0</pose>
        <enable_wind>false</enable_wind>
      </link>
      <joint name='fork_left_wheel_joint' type='revolute'>
        <pose>0 0 -0 0 -0 0</pose>
        <parent>base_link</parent>
        <child>fork_left_wheel</child>
        <axis>
          <xyz>0 0 1</xyz>
          <limit>
            <lower>-10000000000000000</lower>
            <upper>10000000000000000</upper>
            <effort>inf</effort>
            <velocity>inf</velocity>
            <stiffness>100000000</stiffness>
            <dissipation>1</dissipation>
          </limit>
          <dynamics>
            <spring_reference>0</spring_reference>
            <spring_stiffness>0</spring_stiffness>
            <damping>0</damping>
            <friction>0</friction>
          </dynamics>
        </axis>
      </joint>
      <link name='fork_left_wheel'>
        <pose>0.94 0.18 -0.05 -1.5708 0.696862 0</pose>
        <inertial>
          <pose>0 0 0 0 -0 0</pose>
          <mass>0.10000000000000001</mass>
          <inertia>
            <ixx>2.5833299999999999e-05</ixx>
            <ixy>0</ixy>
            <ixz>0</ixz>
            <iyy>2.5833299999999999e-05</iyy>
            <iyz>0</iyz>
            <izz>4.5000000000000003e-05</izz>
          </inertia>
        </inertial>
        <collision name='fork_left_wheel_collision'>
          <pose>0 0 0 0 0 0</pose>
          <geometry>
            <cylinder>
              <length>0.02</length>
              <radius>0.029999999999999999</radius>
            </cylinder>
          </geometry>
          <surface>
            <friction>
              <ode/>
            </friction>
            <bounce/>
            <contact/>
          </surface>
        </collision>
        <visual name='fork_left_wheel_visual'>
          <pose>0 0 0 0 0 0</pose>
          <geometry>
            <cylinder>
              <length>0.02</length>
              <radius>0.029999999999999999</radius>
            </cylinder>
          </geometry>
          <material>
            <diffuse>1 0.375 0.125 1</diffuse>
            <ambient>1 0.375 0.125 1</ambient>
          </material>
        </visual>
        <enable_wind>false</enable_wind>
      </link>
      <joint name='fork_right_wheel_joint' type='revolute'>
        <pose>0 0 0 0 -0 0</pose>
        <parent>base_link</parent>
        <child>fork_right_wheel</child>
        <axis>
          <xyz>0 0 -1</xyz>
          <limit>
            <lower>-10000000000000000</lower>
            <upper>10000000000000000</upper>
            <effort>inf</effort>
            <velocity>inf</velocity>
            <stiffness>100000000</stiffness>
            <dissipation>1</dissipation>
          </limit>
          <dynamics>
            <spring_reference>0</spring_reference>
            <spring_stiffness>0</spring_stiffness>
            <damping>0</damping>
            <friction>0</friction>
          </dynamics>
        </axis>
      </joint>
      <link name='fork_right_wheel'>
        <pose>0.94 -0.18 -0.05 1.5708 0.889555 3.14159</pose>
        <inertial>
          <pose>0 0 0 0 -0 0</pose>
          <mass>0.10000000000000001</mass>
          <inertia>
            <ixx>2.5833299999999999e-05</ixx>
            <ixy>0</ixy>
            <ixz>0</ixz>
            <iyy>2.5833299999999999e-05</iyy>
            <iyz>0</iyz>
            <izz>4.5000000000000003e-05</izz>
          </inertia>
        </inertial>
        <collision name='fork_right_wheel_collision'>
          <pose>0 0 0 0 0 0</pose>
          <geometry>
            <cylinder>
              <length>0.02</length>
              <radius>0.029999999999999999</radius>
            </cylinder>
          </geometry>
          <surface>
            <friction>
              <ode/>
            </friction>
            <bounce/>
            <contact/>
          </surface>
        </collision>
        <visual name='fork_right_wheel_visual'>
          <pose>0 0 0 0 0 0</pose>
          <geometry>
            <cylinder>
              <length>0.02</length>
              <radius>0.029999999999999999</radius>
            </cylinder>
          </geometry>
          <material>
            <diffuse>1 0.375 0.125 1</diffuse>
            <ambient>1 0.375 0.125 1</ambient>
          </material>
        </visual>
        <enable_wind>false</enable_wind>
      </link>
      <joint name='steering_cylinder_joint' type='revolute'>
        <pose>0 0 0 0 -0 0</pose>
        <parent>base_link</parent>
        <child>steering_cylinder</child>
        <axis>
          <xyz>0 0 -1</xyz>
          <limit>
            <lower>-1.5</lower>
            <upper>1.5</upper>
            <effort>10</effort>
            <velocity>1</velocity>
            <stiffness>100000000</stiffness>
            <dissipation>1</dissipation>
          </limit>
          <dynamics>
            <spring_reference>0</spring_reference>
            <spring_stiffness>0</spring_stiffness>
            <damping>0</damping>
            <friction>0</friction>
          </dynamics>
        </axis>
      </joint>
      <link name='steering_cylinder'>
        <pose>-0.01 -0 0.1 -0 0 1.5708</pose>
        <inertial>
          <pose>0 0 0 0 -0 0</pose>
          <mass>0.10000000000000001</mass>
          <inertia>
            <ixx>0.00033583300000000001</ixx>
            <ixy>0</ixy>
            <ixz>0</ixz>
            <iyy>0.00033583300000000001</iyy>
            <iyz>0</iyz>
            <izz>5.0000000000000004e-06</izz>
          </inertia>
        </inertial>
        <collision name='steering_cylinder_collision'>
          <pose>0 0 0 0 0 0</pose>
          <geometry>
            <cylinder>
              <length>0.20000000000000001</length>
              <radius>0.01</radius>
            </cylinder>
          </geometry>
          <surface>
            <friction>
              <ode/>
            </friction>
            <bounce/>
            <contact/>
          </surface>
        </collision>
        <visual name='steering_cylinder_visual'>
          <pose>0 0 0 0 0 0</pose>
          <geometry>
            <cylinder>
              <length>0.20000000000000001</length>
              <radius>0.01</radius>
            </cylinder>
          </geometry>
          <material>
            <diffuse>0.25 0.25 1 1</diffuse>
            <ambient>0.25 0.25 1 1</ambient>
          </material>
        </visual>
        <enable_wind>false</enable_wind>
      </link>
      <joint name='front_wheel_joint' type='revolute'>
        <pose>0 0 0 0 -0 0</pose>
        <parent>steering_cylinder</parent>
        <child>front_wheel</child>
        <axis>
          <xyz>0 0 1</xyz>
          <limit>
            <lower>-10000000000000000</lower>
            <upper>10000000000000000</upper>
            <effort>inf</effort>
            <velocity>inf</velocity>
            <stiffness>100000000</stiffness>
            <dissipation>1</dissipation>
          </limit>
          <dynamics>
            <spring_reference>0</spring_reference>
            <spring_stiffness>0</spring_stiffness>
            <damping>0</damping>
            <friction>0</friction>
          </dynamics>
        </axis>
      </joint>
      <link name='front_wheel'>
        <pose>-0.01 -0 0 -1.5708 -0.061121 -0</pose>
        <inertial>
          <pose>0 0 0 0 -0 0</pose>
          <mass>0.10000000000000001</mass>
          <inertia>
            <ixx>0.000135833</ixx>
            <ixy>0</ixy>
            <ixz>0</ixz>
            <iyy>0.000135833</iyy>
            <iyz>0</iyz>
            <izz>0.00024499999999999999</izz>
          </inertia>
        </inertial>
        <collision name='front_wheel_collision'>
          <pose>0 0 0 0 0 0</pose>
          <geometry>
            <cylinder>
              <length>0.040000000000000001</length>
              <radius>0.070000000000000007</radius>
            </cylinder>
          </geometry>
          <surface>
            <friction>
              <ode/>
            </friction>
            <bounce/>
            <contact/>
          </surface>
        </collision>
        <visual name='front_wheel_visual'>
          <pose>0 0 0 0 0 0</pose>
          <geometry>
            <cylinder>
              <length>0.040000000000000001</length>
              <radius>0.070000000000000007</radius>
            </cylinder>
          </geometry>
          <material>
            <diffuse>1 0.375 0.125 1</diffuse>
            <ambient>1 0.375 0.125 1</ambient>
          </material>
        </visual>
        <enable_wind>false</enable_wind>
      </link>
      <plugin name='gz_ros2_control::GazeboSimROS2ControlPlugin' filename='gz_ros2_control-system'>
        <parameters>/home/kalerobot/ros2_ws/install/agv_project/share/agv_project/config/controllers_tricycle.yaml</parameters>
      </plugin>
      <frame name='base_footprint_joint' attached_to='base_link'>
        <pose>0 0 0 0 -0 0</pose>
      </frame>
      <frame name='base_footprint' attached_to='base_footprint_joint'/>
      <frame name='laser_joint' attached_to='base_link'>
        <pose>0.075 0 0.2125 0 -0 0</pose>
      </frame>
      <frame name='laser' attached_to='laser_joint'/>
      <frame name='left_fork_joint' attached_to='base_link'>
        <pose>0 0.18 -0.05 0 -0 0</pose>
      </frame>
      <frame name='left_fork' attached_to='left_fork_joint'/>
      <frame name='right_fork_joint' attached_to='base_link'>
        <pose>0 -0.18 -0.05 0 -0 0</pose>
      </frame>
      <frame name='right_fork' attached_to='right_fork_joint'/>
      <pose>1.67874 0.145951 0.070105 -0 -0.010524 -3.00555</pose>
      <static>false</static>
      <self_collide>false</self_collide>
    </model>
    <model name='box'>
      <pose>1.80492 1.99194 0.5 0 0 -0</pose>
      <link name='box_link'>
        <inertial>
          <inertia>
            <ixx>0.16666</ixx>
            <ixy>0</ixy>
            <ixz>0</ixz>
            <iyy>0.16666</iyy>
            <iyz>0</iyz>
            <izz>0.16666</izz>
          </inertia>
          <mass>1</mass>
          <pose>0 0 0 0 -0 0</pose>
        </inertial>
        <collision name='box_collision'>
          <geometry>
            <box>
              <size>1 1 1</size>
            </box>
          </geometry>
          <surface>
            <friction>
              <ode/>
            </friction>
            <bounce/>
            <contact/>
          </surface>
        </collision>
        <visual name='box_visual'>
          <geometry>
            <box>
              <size>1 1 1</size>
            </box>
          </geometry>
          <material>
            <ambient>0.3 0.3 0.3 1</ambient>
            <diffuse>0.7 0.7 0.7 1</diffuse>
            <specular>1 1 1 1</specular>
          </material>
        </visual>
        <pose>0 0 0 0 -0 0</pose>
        <enable_wind>false</enable_wind>
      </link>
      <static>false</static>
      <self_collide>false</self_collide>
    </model>
    <model name='box_0'>
      <pose>0.596653 1.95376 0.5 0 0 0</pose>
      <link name='box_link'>
        <inertial>
          <inertia>
            <ixx>0.16666</ixx>
            <ixy>0</ixy>
            <ixz>0</ixz>
            <iyy>0.16666</iyy>
            <iyz>0</iyz>
            <izz>0.16666</izz>
          </inertia>
          <mass>1</mass>
          <pose>0 0 0 0 -0 0</pose>
        </inertial>
        <collision name='box_collision'>
          <geometry>
            <box>
              <size>1 1 1</size>
            </box>
          </geometry>
          <surface>
            <friction>
              <ode/>
            </friction>
            <bounce/>
            <contact/>
          </surface>
        </collision>
        <visual name='box_visual'>
          <geometry>
            <box>
              <size>1 1 1</size>
            </box>
          </geometry>
          <material>
            <ambient>0.3 0.3 0.3 1</ambient>
            <diffuse>0.7 0.7 0.7 1</diffuse>
            <specular>1 1 1 1</specular>
          </material>
        </visual>
        <pose>0 0 0 0 -0 0</pose>
        <enable_wind>false</enable_wind>
      </link>
      <static>false</static>
      <self_collide>false</self_collide>
    </model>
    <model name='box_1'>
      <pose>-0.513079 1.91947 0.5 0 0 -0</pose>
      <link name='box_link'>
        <inertial>
          <inertia>
            <ixx>0.16666</ixx>
            <ixy>0</ixy>
            <ixz>0</ixz>
            <iyy>0.16666</iyy>
            <iyz>0</iyz>
            <izz>0.16666</izz>
          </inertia>
          <mass>1</mass>
          <pose>0 0 0 0 -0 0</pose>
        </inertial>
        <collision name='box_collision'>
          <geometry>
            <box>
              <size>1 1 1</size>
            </box>
          </geometry>
          <surface>
            <friction>
              <ode/>
            </friction>
            <bounce/>
            <contact/>
          </surface>
        </collision>
        <visual name='box_visual'>
          <geometry>
            <box>
              <size>1 1 1</size>
            </box>
          </geometry>
          <material>
            <ambient>0.3 0.3 0.3 1</ambient>
            <diffuse>0.7 0.7 0.7 1</diffuse>
            <specular>1 1 1 1</specular>
          </material>
        </visual>
        <pose>0 0 0 0 -0 0</pose>
        <enable_wind>false</enable_wind>
      </link>
      <static>false</static>
      <self_collide>false</self_collide>
    </model>
    <model name='box_2'>
      <pose>-1.66275 1.87481 0.5 0 0 -0</pose>
      <link name='box_link'>
        <inertial>
          <inertia>
            <ixx>0.16666</ixx>
            <ixy>0</ixy>
            <ixz>0</ixz>
            <iyy>0.16666</iyy>
            <iyz>0</iyz>
            <izz>0.16666</izz>
          </inertia>
          <mass>1</mass>
          <pose>0 0 0 0 -0 0</pose>
        </inertial>
        <collision name='box_collision'>
          <geometry>
            <box>
              <size>1 1 1</size>
            </box>
          </geometry>
          <surface>
            <friction>
              <ode/>
            </friction>
            <bounce/>
            <contact/>
          </surface>
        </collision>
        <visual name='box_visual'>
          <geometry>
            <box>
              <size>1 1 1</size>
            </box>
          </geometry>
          <material>
            <ambient>0.3 0.3 0.3 1</ambient>
            <diffuse>0.7 0.7 0.7 1</diffuse>
            <specular>1 1 1 1</specular>
          </material>
        </visual>
        <pose>0 0 0 0 -0 0</pose>
        <enable_wind>false</enable_wind>
      </link>
      <static>false</static>
      <self_collide>false</self_collide>
    </model>
    <model name='box_3'>
      <pose>-1.71365 0.788314 0.5 -0 -0 0</pose>
      <link name='box_link'>
        <inertial>
          <inertia>
            <ixx>0.16666</ixx>
            <ixy>0</ixy>
            <ixz>0</ixz>
            <iyy>0.16666</iyy>
            <iyz>0</iyz>
            <izz>0.16666</izz>
          </inertia>
          <mass>1</mass>
          <pose>0 0 0 0 -0 0</pose>
        </inertial>
        <collision name='box_collision'>
          <geometry>
            <box>
              <size>1 1 1</size>
            </box>
          </geometry>
          <surface>
            <friction>
              <ode/>
            </friction>
            <bounce/>
            <contact/>
          </surface>
        </collision>
        <visual name='box_visual'>
          <geometry>
            <box>
              <size>1 1 1</size>
            </box>
          </geometry>
          <material>
            <ambient>0.3 0.3 0.3 1</ambient>
            <diffuse>0.7 0.7 0.7 1</diffuse>
            <specular>1 1 1 1</specular>
          </material>
        </visual>
        <pose>0 0 0 0 -0 0</pose>
        <enable_wind>false</enable_wind>
      </link>
      <static>false</static>
      <self_collide>false</self_collide>
    </model>
    <model name='box_4'>
      <pose>-2.34125 -0.249698 0.5 -0 -0 0.018052</pose>
      <link name='box_link'>
        <inertial>
          <inertia>
            <ixx>0.16666</ixx>
            <ixy>0</ixy>
            <ixz>0</ixz>
            <iyy>0.16666</iyy>
            <iyz>0</iyz>
            <izz>0.16666</izz>
          </inertia>
          <mass>1</mass>
          <pose>0 0 0 0 -0 0</pose>
        </inertial>
        <collision name='box_collision'>
          <geometry>
            <box>
              <size>1 1 1</size>
            </box>
          </geometry>
          <surface>
            <friction>
              <ode/>
            </friction>
            <bounce/>
            <contact/>
          </surface>
        </collision>
        <visual name='box_visual'>
          <geometry>
            <box>
              <size>1 1 1</size>
            </box>
          </geometry>
          <material>
            <ambient>0.3 0.3 0.3 1</ambient>
            <diffuse>0.7 0.7 0.7 1</diffuse>
            <specular>1 1 1 1</specular>
          </material>
        </visual>
        <pose>0 0 0 0 -0 0</pose>
        <enable_wind>false</enable_wind>
      </link>
      <static>false</static>
      <self_collide>false</self_collide>
    </model>
    <model name='box_5'>
      <pose>-1.71365 -1.291 0.5 0 0 -0</pose>
      <link name='box_link'>
        <inertial>
          <inertia>
            <ixx>0.16666</ixx>
            <ixy>0</ixy>
            <ixz>0</ixz>
            <iyy>0.16666</iyy>
            <iyz>0</iyz>
            <izz>0.16666</izz>
          </inertia>
          <mass>1</mass>
          <pose>0 0 0 0 -0 0</pose>
        </inertial>
        <collision name='box_collision'>
          <geometry>
            <box>
              <size>1 1 1</size>
            </box>
          </geometry>
          <surface>
            <friction>
              <ode/>
            </friction>
            <bounce/>
            <contact/>
          </surface>
        </collision>
        <visual name='box_visual'>
          <geometry>
            <box>
              <size>1 1 1</size>
            </box>
          </geometry>
          <material>
            <ambient>0.3 0.3 0.3 1</ambient>
            <diffuse>0.7 0.7 0.7 1</diffuse>
            <specular>1 1 1 1</specular>
          </material>
        </visual>
        <pose>0 0 0 0 -0 0</pose>
        <enable_wind>false</enable_wind>
      </link>
      <static>false</static>
      <self_collide>false</self_collide>
    </model>
    <model name='box_6'>
      <pose>-1.71365 -2.31924 0.5 0 0 -0</pose>
      <link name='box_link'>
        <inertial>
          <inertia>
            <ixx>0.16666</ixx>
            <ixy>0</ixy>
            <ixz>0</ixz>
            <iyy>0.16666</iyy>
            <iyz>0</iyz>
            <izz>0.16666</izz>
          </inertia>
          <mass>1</mass>
          <pose>0 0 0 0 -0 0</pose>
        </inertial>
        <collision name='box_collision'>
          <geometry>
            <box>
              <size>1 1 1</size>
            </box>
          </geometry>
          <surface>
            <friction>
              <ode/>
            </friction>
            <bounce/>
            <contact/>
          </surface>
        </collision>
        <visual name='box_visual'>
          <geometry>
            <box>
              <size>1 1 1</size>
            </box>
          </geometry>
          <material>
            <ambient>0.3 0.3 0.3 1</ambient>
            <diffuse>0.7 0.7 0.7 1</diffuse>
            <specular>1 1 1 1</specular>
          </material>
        </visual>
        <pose>0 0 0 0 -0 0</pose>
        <enable_wind>false</enable_wind>
      </link>
      <static>false</static>
      <self_collide>false</self_collide>
    </model>
    <model name='box_7'>
      <pose>-0.682948 -2.29867 0.5 0 -0 -1e-06</pose>
      <link name='box_link'>
        <inertial>
          <inertia>
            <ixx>0.16666</ixx>
            <ixy>0</ixy>
            <ixz>0</ixz>
            <iyy>0.16666</iyy>
            <iyz>0</iyz>
            <izz>0.16666</izz>
          </inertia>
          <mass>1</mass>
          <pose>0 0 0 0 -0 0</pose>
        </inertial>
        <collision name='box_collision'>
          <geometry>
            <box>
              <size>1 1 1</size>
            </box>
          </geometry>
          <surface>
            <friction>
              <ode/>
            </friction>
            <bounce/>
            <contact/>
          </surface>
        </collision>
        <visual name='box_visual'>
          <geometry>
            <box>
              <size>1 1 1</size>
            </box>
          </geometry>
          <material>
            <ambient>0.3 0.3 0.3 1</ambient>
            <diffuse>0.7 0.7 0.7 1</diffuse>
            <specular>1 1 1 1</specular>
          </material>
        </visual>
        <pose>0 0 0 0 -0 0</pose>
        <enable_wind>false</enable_wind>
      </link>
      <static>false</static>
      <self_collide>false</self_collide>
    </model>
    <model name='box_8'>
      <pose>0.317051 -2.30085 0.5 0 0 -1e-06</pose>
      <link name='box_link'>
        <inertial>
          <inertia>
            <ixx>0.16666</ixx>
            <ixy>0</ixy>
            <ixz>0</ixz>
            <iyy>0.16666</iyy>
            <iyz>0</iyz>
            <izz>0.16666</izz>
          </inertia>
          <mass>1</mass>
          <pose>0 0 0 0 -0 0</pose>
        </inertial>
        <collision name='box_collision'>
          <geometry>
            <box>
              <size>1 1 1</size>
            </box>
          </geometry>
          <surface>
            <friction>
              <ode/>
            </friction>
            <bounce/>
            <contact/>
          </surface>
        </collision>
        <visual name='box_visual'>
          <geometry>
            <box>
              <size>1 1 1</size>
            </box>
          </geometry>
          <material>
            <ambient>0.3 0.3 0.3 1</ambient>
            <diffuse>0.7 0.7 0.7 1</diffuse>
            <specular>1 1 1 1</specular>
          </material>
        </visual>
        <pose>0 0 0 0 -0 0</pose>
        <enable_wind>false</enable_wind>
      </link>
      <static>false</static>
      <self_collide>false</self_collide>
    </model>
    <model name='box_9'>
      <pose>1.33177 -2.32491 0.5 -0 -0 -1e-06</pose>
      <link name='box_link'>
        <inertial>
          <inertia>
            <ixx>0.16666</ixx>
            <ixy>0</ixy>
            <ixz>0</ixz>
            <iyy>0.16666</iyy>
            <iyz>0</iyz>
            <izz>0.16666</izz>
          </inertia>
          <mass>1</mass>
          <pose>0 0 0 0 -0 0</pose>
        </inertial>
        <collision name='box_collision'>
          <geometry>
            <box>
              <size>1 1 1</size>
            </box>
          </geometry>
          <surface>
            <friction>
              <ode/>
            </friction>
            <bounce/>
            <contact/>
          </surface>
        </collision>
        <visual name='box_visual'>
          <geometry>
            <box>
              <size>1 1 1</size>
            </box>
          </geometry>
          <material>
            <ambient>0.3 0.3 0.3 1</ambient>
            <diffuse>0.7 0.7 0.7 1</diffuse>
            <specular>1 1 1 1</specular>
          </material>
        </visual>
        <pose>0 0 0 0 -0 0</pose>
        <enable_wind>false</enable_wind>
      </link>
      <static>false</static>
      <self_collide>false</self_collide>
    </model>
    <model name='box_10'>
      <pose>2.33177 -2.32889 0.5 0 0 -1e-06</pose>
      <link name='box_link'>
        <inertial>
          <inertia>
            <ixx>0.16666</ixx>
            <ixy>0</ixy>
            <ixz>0</ixz>
            <iyy>0.16666</iyy>
            <iyz>0</iyz>
            <izz>0.16666</izz>
          </inertia>
          <mass>1</mass>
          <pose>0 0 0 0 -0 0</pose>
        </inertial>
        <collision name='box_collision'>
          <geometry>
            <box>
              <size>1 1 1</size>
            </box>
          </geometry>
          <surface>
            <friction>
              <ode/>
            </friction>
            <bounce/>
            <contact/>
          </surface>
        </collision>
        <visual name='box_visual'>
          <geometry>
            <box>
              <size>1 1 1</size>
            </box>
          </geometry>
          <material>
            <ambient>0.3 0.3 0.3 1</ambient>
            <diffuse>0.7 0.7 0.7 1</diffuse>
            <specular>1 1 1 1</specular>
          </material>
        </visual>
        <pose>0 0 0 0 -0 0</pose>
        <enable_wind>false</enable_wind>
      </link>
      <static>false</static>
      <self_collide>false</self_collide>
    </model>
    <light name='sun' type='directional'>
      <pose>0 0 10 0 -0 0</pose>
      <cast_shadows>true</cast_shadows>
      <intensity>1</intensity>
      <direction>-0.5 0.1 -0.9</direction>
      <diffuse>0.8 0.8 0.8 1</diffuse>
      <specular>0.2 0.2 0.2 1</specular>
      <attenuation>
        <range>1000</range>
        <linear>0.01</linear>
        <constant>0.90000000000000002</constant>
        <quadratic>0.001</quadratic>
      </attenuation>
      <spot>
        <inner_angle>0</inner_angle>
        <outer_angle>0</outer_angle>
        <falloff>0</falloff>
      </spot>
    </light>
  </world>
</sdf>
